<?xml version="1.0" ?>

<sdf version="1.8">
  <world name="demo">
    <plugin
      filename="gz-sim-physics-system"
      name="gz::sim::systems::Physics">
    </plugin>
    <plugin
      filename="gz-sim-sensors-system"
      name="gz::sim::systems::Sensors">
      <render_engine>ogre2</render_engine>
    </plugin>
    <plugin
      filename="gz-sim-scene-broadcaster-system"
      name="gz::sim::systems::SceneBroadcaster">
    </plugin>
    <plugin
      filename="gz-sim-user-commands-system"
      name="gz::sim::systems::UserCommands">
    </plugin>

  <gui fullscreen="0">
      <plugin filename="GzScene3D" name="3D View">
        <gz-gui>
          <title>3D View</title>
          <property key="showTitleBar" type="bool">false</property>
          <property key="state" type="string">docked</property>
        </gz-gui>
        <engine>ogre2</engine>
        <scene>scene</scene>
        <ambient_light>0.4 0.4 0.4</ambient_light>
        <background_color>0.8 0.8 0.8</background_color>
        <camera_pose>-6 0 6 0 0.5 0</camera_pose>
      </plugin>

      <plugin filename="WorldControl" name="World control">
        <gz-gui>
          <title>World control</title>
          <property type="bool" key="showTitleBar">false</property>
          <property type="bool" key="resizable">false</property>
          <property type="double" key="height">72</property>
          <property type="double" key="width">150</property>
          <property type="double" key="z">1</property>
          <property type="string" key="state">floating</property>
          <anchors target="3D View">
            <line own="left" target="left" />
            <line own="bottom" target="bottom" />
          </anchors>
        </gz-gui>
        <play_pause>true</play_pause>
        <step>true</step>
        <start_paused>true</start_paused>
        <use_event>false</use_event>
        <start_paused>true</start_paused>

      </plugin>

      <plugin filename="WorldStats" name="World stats">
        <gz-gui>
          <title>World stats</title>
          <property type="bool" key="showTitleBar">false</property>
          <property type="bool" key="resizable">false</property>
          <property type="double" key="height">110</property>
          <property type="double" key="width">290</property>
          <property type="double" key="z">1</property>
          <property type="string" key="state">floating</property>
          <anchors target="3D View">
            <line own="right" target="right" />
            <line own="bottom" target="bottom" />
          </anchors>
        </gz-gui>
        <sim_time>false</sim_time>
        <real_time>false</real_time>
        <real_time_factor>true</real_time_factor>
        <iterations>true</iterations>
      </plugin>
      
      <plugin filename="KeyPublisher" name="Key publisher">
        <gz-gui>
          <anchors target="3D View">
            <line own="right" target="right" />
            <line own="top" target="top" />
          </anchors>
          <property key="resizable" type="bool">true</property>
          <property key="width" type="double">5</property>
          <property key="height" type="double">5</property>
          <property key="state" type="string">floating</property>
          <property key="showTitleBar" type="bool">false</property>
        </gz-gui>
      </plugin>
    </gui>

    <light name="sun" type="directional">
      <cast_shadows>true</cast_shadows>
      <pose>0 0 10 0 0 0</pose>
      <diffuse>0.8 0.8 0.8 1</diffuse>
      <specular>0.2 0.2 0.2 1</specular>
      <attenuation>
        <range>1000</range>
        <constant>0.9</constant>
        <linear>0.01</linear>
        <quadratic>0.001</quadratic>
      </attenuation>
      <direction>-0.5 0.1 -0.9</direction>
    </light>

    <model name="ground_plane">
      <static>true</static>
      <link name="link">
        <collision name="collision">
          <geometry>
            <plane>
              <normal>0 0 1</normal>
              <size>100 100</size>
            </plane>
          </geometry>
        </collision>
        <visual name="visual">
          <geometry>
            <plane>
              <normal>0 0 1</normal>
              <size>100 100</size>
            </plane>
          </geometry>
          <material>
            <ambient>0.8 0.8 0.8 1</ambient>
            <diffuse>0.8 0.8 0.8 1</diffuse>
            <specular>0.8 0.8 0.8 1</specular>
          </material>
        </visual>
      </link>
    </model>

    <model name="vehicle_blue">
      <self_collide>true</self_collide>
      <pose>-3 0 0.35 0 0 0</pose>
      <include merge="true">
        <uri>package://ros_gz_example_description/models/mecanum_drive</uri>
      </include>

      <plugin
        filename="gz-sim-pose-publisher-system"
        name="gz::sim::systems::PosePublisher">
        <publish_link_pose>false</publish_link_pose> 
        <publish_model_pose>true</publish_model_pose>
        <use_pose_vector_msg>false</use_pose_vector_msg>
        <static_publisher>false</static_publisher> 
        <update_frequency>20</update_frequency>
      </plugin>

      <plugin
        filename="gz-sim-odometry-publisher-system"
        name="gz::sim::systems::OdometryPublisher">
        <odom_topic>/model/vehicle_blue/odometry</odom_topic>
        <odom_frame>vehicle_blue/odom</odom_frame>
        <robot_base_frame>vehicle_blue</robot_base_frame>
        <odom_publish_frequency>20</odom_publish_frequency>
      </plugin>

    </model>

    <model name='movable_long_obstacle' canonical_link='chassis'>
            <pose relative_to='world'>0 8 0 0 0 -1.5707</pose>   
            
            <link name='chassis'>
                <pose relative_to='__model__'>0.5 0 0.4 0 0 0</pose>
                <inertial> 
                    <mass>1.14395</mass>
                    <inertia>
                        <ixx>0.095329</ixx>
                        <ixy>0</ixy>
                        <ixz>0</ixz>
                        <iyy>0.381317</iyy>
                        <iyz>0</iyz>
                        <izz>0.476646</izz>
                    </inertia>
                </inertial>
                <visual name='visual'>
                    <geometry>
                        <box>
                            <size>13.0 2.0 0.5</size>
                        </box>
                    </geometry>
                    
                    <material>
                        <ambient>0.0 0.0 1.0 1</ambient>
                        <diffuse>0.0 0.0 1.0 1</diffuse>
                        <specular>0.0 0.0 1.0 1</specular>
                    </material>
                </visual>
                <collision name='collision'>
                    <geometry>
                        <box>
                            <size>13.0 2.0 0.5</size>
                        </box>
                    </geometry>
                </collision>
            </link>

            <link name='left_wheel'>
                <pose relative_to="chassis">-0.5 0.6 0 -1.5707 0 0</pose> 
                <inertial>
                    <mass>1</mass>
                    <inertia>
                        <ixx>0.043333</ixx>
                        <ixy>0</ixy>
                        <ixz>0</ixz>
                        <iyy>0.043333</iyy>
                        <iyz>0</iyz>
                        <izz>0.08</izz>
                    </inertia>
                </inertial>
                <visual name='visual'>
                    <geometry>
                        <cylinder>
                            <radius>0.4</radius>
                            <length>0.2</length>
                        </cylinder>
                    </geometry>
                    <material>
                        <ambient>1.0 0.0 0.0 1</ambient>
                        <diffuse>1.0 0.0 0.0 1</diffuse>
                        <specular>1.0 0.0 0.0 1</specular>
                    </material>
                </visual>
                <collision name='collision'>
                    <geometry>
                        <cylinder>
                            <radius>0.4</radius>
                            <length>0.2</length>
                        </cylinder>
                    </geometry>
                </collision>
            </link>
            
            <link name='right_wheel'>
                <pose relative_to="chassis">-0.5 -0.6 0 -1.5707 0 0</pose> 
                <inertial>
                    <mass>1</mass>
                    <inertia>
                        <ixx>0.043333</ixx>
                        <ixy>0</ixy>
                        <ixz>0</ixz>
                        <iyy>0.043333</iyy>
                        <iyz>0</iyz>
                        <izz>0.08</izz>
                    </inertia>
                </inertial>
                <visual name='visual'>
                    <geometry>
                        <cylinder>
                            <radius>0.4</radius>
                            <length>0.2</length>
                        </cylinder>
                    </geometry>
                    <material>
                        <ambient>1.0 0.0 0.0 1</ambient>
                        <diffuse>1.0 0.0 0.0 1</diffuse>
                        <specular>1.0 0.0 0.0 1</specular>
                    </material>
                </visual>
                <collision name='collision'>
                    <geometry>
                        <cylinder>
                            <radius>0.4</radius>
                            <length>0.2</length>
                        </cylinder>
                    </geometry>
                </collision>
            </link>

            <frame name="caster_frame" attached_to='chassis'>
                <pose>0.8 0 -0.2 0 0 0</pose>
            </frame>
            
            <link name='caster'>
                <pose relative_to='caster_frame'/>
                <inertial>
                    <mass>1</mass>
                    <inertia>
                        <ixx>0.016</ixx>
                        <ixy>0</ixy>
                        <ixz>0</ixz>
                        <iyy>0.016</iyy>
                        <iyz>0</iyz>
                        <izz>0.016</izz>
                    </inertia>
                </inertial>
                <visual name='visual'>
                    <geometry>
                        <sphere>
                            <radius>0.2</radius>
                        </sphere>
                    </geometry>
                    <material>
                        <ambient>0.0 1 0.0 1</ambient>
                        <diffuse>0.0 1 0.0 1</diffuse>
                        <specular>0.0 1 0.0 1</specular>
                    </material>
                </visual>
                <collision name='collision'>
                    <geometry>
                        <sphere>
                            <radius>0.2</radius>
                        </sphere>
                    </geometry>
                </collision>
            </link>

            <joint name='left_wheel_joint' type='revolute'>
                <pose relative_to='left_wheel'/>
                <parent>chassis</parent>
                <child>left_wheel</child>
                <axis>
                    <xyz expressed_in='__model__'>0 1 0</xyz> 
                    <limit>
                        <lower>-1.79769e+308</lower>    
                        <upper>1.79769e+308</upper>     
                    </limit>
                </axis>
            </joint>
            
            <joint name='right_wheel_joint' type='revolute'>
                <pose relative_to='right_wheel'/>
                <parent>chassis</parent>
                <child>right_wheel</child>
                <axis>
                    <xyz expressed_in='__model__'>0 1 0</xyz>
                    <limit>
                        <lower>-1.79769e+308</lower>    
                        <upper>1.79769e+308</upper>     
                    </limit>
                </axis>
            </joint>

            <joint name='caster_wheel' type='ball'>
                <parent>chassis</parent>
                <child>caster</child>
            </joint>

            <plugin
                filename="gz-sim-diff-drive-system"
                name="gz::sim::systems::DiffDrive">
                <left_joint>left_wheel_joint</left_joint>
                <right_joint>right_wheel_joint</right_joint>
                <wheel_separation>1.2</wheel_separation>
                <wheel_radius>0.4</wheel_radius>
                <odom_publish_frequency>20</odom_publish_frequency>
                <odom_topic>/model/movable_long_obstacle/odometry</odom_topic>
                <topic>/model/movable_long_obstacle/cmd_vel</topic>
                <publish_odom>true</publish_odom>
                <publish_tf>false</publish_tf>
            </plugin>
        </model>

        <plugin filename="gz-sim-triggered-publisher-system"
                name="gz::sim::systems::TriggeredPublisher">
            <input type="gz.msgs.Int32" topic="/keyboard/keypress">
                <match field="data">87</match>
            </input>
            <output type="gz.msgs.Twist" topic="/model/vehicle_blue/cmd_vel">
                linear: {x: 2}, angular: {z: 0.0}
            </output>
        </plugin>
        
        <plugin filename="gz-sim-triggered-publisher-system"
                name="gz::sim::systems::TriggeredPublisher">
            <input type="gz.msgs.Int32" topic="/keyboard/keypress">
                <match field="data">68</match>
            </input>
            <output type="gz.msgs.Twist" topic="/model/vehicle_blue/cmd_vel">
                linear: {y: -2}, angular: {z: 0.0}
            </output>
        </plugin>

        <plugin filename="gz-sim-triggered-publisher-system"
                name="gz::sim::systems::TriggeredPublisher">
            <input type="gz.msgs.Int32" topic="/keyboard/keypress">
                <match field="data">65</match>
            </input>
            <output type="gz.msgs.Twist" topic="/model/vehicle_blue/cmd_vel">
                linear: {y: 2}, angular: {z: 0.0}
            </output>
        </plugin>

        <plugin filename="gz-sim-triggered-publisher-system"
                name="gz::sim::systems::TriggeredPublisher">
            <input type="gz.msgs.Int32" topic="/keyboard/keypress">
                <match field="data">83</match>
            </input>
            <output type="gz.msgs.Twist" topic="/model/vehicle_blue/cmd_vel">
                linear: {x: -2}, angular: {z: 0.0}
            </output>
        </plugin>

        <plugin filename="gz-sim-triggered-publisher-system"
                name="gz::sim::systems::TriggeredPublisher">
            <input type="gz.msgs.Int32" topic="/keyboard/keypress">
                <match field="data">16777235</match>
            </input>
            <output type="gz.msgs.Twist" topic="/model/vehicle_blue/cmd_vel">
                linear: {x: 3}, angular: {z: 0.0}
            </output>
        </plugin>
        

        <plugin filename="gz-sim-triggered-publisher-system"
                name="gz::sim::systems::TriggeredPublisher">
            <input type="gz.msgs.Int32" topic="/keyboard/keypress">
                <match field="data">16777237</match>
            </input>
            <output type="gz.msgs.Twist" topic="/model/vehicle_blue/cmd_vel">
                linear: {x: -3}, angular: {z: 0.0}
            </output>
        </plugin>

        <plugin filename="gz-sim-triggered-publisher-system"
                name="gz::sim::systems::TriggeredPublisher">
            <input type="gz.msgs.Int32" topic="/keyboard/keypress">
                <match field="data">16777236</match>
            </input>
            <output type="gz.msgs.Twist" topic="/model/vehicle_blue/cmd_vel">
                linear: {y: 0}, angular: {z: -0.5}
            </output>
        </plugin>

        <plugin filename="gz-sim-triggered-publisher-system"
                name="gz::sim::systems::TriggeredPublisher">
            <input type="gz.msgs.Int32" topic="/keyboard/keypress">
                <match field="data">16777234</match>
            </input>
            <output type="gz.msgs.Twist" topic="/model/vehicle_blue/cmd_vel">
                linear: {y: 0}, angular: {z: 0.5}
            </output>
        </plugin>


        <plugin filename="gz-sim-triggered-publisher-system"   
                name="gz::sim::systems::TriggeredPublisher">
            <input type="gz.msgs.Int32" topic="/keyboard/keypress">
                <match field="data">16777248</match>
            </input>
            <output type="gz.msgs.Twist" topic="/model/vehicle_blue/cmd_vel">
                linear: {x: 0.0}, angular: {z: 0.0}
            </output>
        </plugin> 

  </world>
</sdf>
